[2024-03-17T01:29:26.740+0000] {taskinstance.py:1083} INFO - Dependencies all met for <TaskInstance: Airflow_Lab2.send_email manual__2024-03-17T01:29:13.341956+00:00 [queued]>
[2024-03-17T01:29:26.747+0000] {taskinstance.py:1083} INFO - Dependencies all met for <TaskInstance: Airflow_Lab2.send_email manual__2024-03-17T01:29:13.341956+00:00 [queued]>
[2024-03-17T01:29:26.748+0000] {taskinstance.py:1279} INFO - 
--------------------------------------------------------------------------------
[2024-03-17T01:29:26.748+0000] {taskinstance.py:1280} INFO - Starting attempt 1 of 1
[2024-03-17T01:29:26.748+0000] {taskinstance.py:1281} INFO - 
--------------------------------------------------------------------------------
[2024-03-17T01:29:26.758+0000] {taskinstance.py:1300} INFO - Executing <Task(EmailOperator): send_email> on 2024-03-17 01:29:13.341956+00:00
[2024-03-17T01:29:26.766+0000] {standard_task_runner.py:55} INFO - Started process 2022 to run task
[2024-03-17T01:29:26.771+0000] {standard_task_runner.py:82} INFO - Running: ['***', 'tasks', 'run', 'Airflow_Lab2', 'send_email', 'manual__2024-03-17T01:29:13.341956+00:00', '--job-id', '64', '--raw', '--subdir', 'DAGS_FOLDER/main.py', '--cfg-path', '/tmp/tmpx0rm4ft5']
[2024-03-17T01:29:26.776+0000] {standard_task_runner.py:83} INFO - Job 64: Subtask send_email
[2024-03-17T01:29:26.838+0000] {task_command.py:388} INFO - Running <TaskInstance: Airflow_Lab2.send_email manual__2024-03-17T01:29:13.341956+00:00 [running]> on host 3dffa19c86ca
[2024-03-17T01:29:26.908+0000] {taskinstance.py:1509} INFO - Exporting the following env vars:
AIRFLOW_CTX_DAG_OWNER=***
AIRFLOW_CTX_DAG_ID=Airflow_Lab2
AIRFLOW_CTX_TASK_ID=send_email
AIRFLOW_CTX_EXECUTION_DATE=2024-03-17T01:29:13.341956+00:00
AIRFLOW_CTX_TRY_NUMBER=1
AIRFLOW_CTX_DAG_RUN_ID=manual__2024-03-17T01:29:13.341956+00:00
[2024-03-17T01:29:26.921+0000] {warnings.py:110} WARNING - /home/***/.local/lib/python3.7/site-packages/***/utils/email.py:152: RemovedInAirflow3Warning: Fetching SMTP credentials from configuration variables will be deprecated in a future release. Please set credentials using a connection instead.
  send_mime_email(e_from=mail_from, e_to=recipients, mime_msg=msg, conn_id=conn_id, dryrun=dryrun)

[2024-03-17T01:29:26.921+0000] {email.py:268} INFO - Email alerting: attempt 1
[2024-03-17T01:29:27.811+0000] {taskinstance.py:1768} ERROR - Task failed with exception
Traceback (most recent call last):
  File "/home/airflow/.local/lib/python3.7/site-packages/airflow/operators/email.py", line 87, in execute
    custom_headers=self.custom_headers,
  File "/home/airflow/.local/lib/python3.7/site-packages/airflow/utils/email.py", line 91, in send_email
    **kwargs,
  File "/home/airflow/.local/lib/python3.7/site-packages/airflow/utils/email.py", line 152, in send_email_smtp
    send_mime_email(e_from=mail_from, e_to=recipients, mime_msg=msg, conn_id=conn_id, dryrun=dryrun)
  File "/home/airflow/.local/lib/python3.7/site-packages/airflow/utils/email.py", line 279, in send_mime_email
    smtp_conn.login(smtp_user, smtp_password)
  File "/usr/local/lib/python3.7/smtplib.py", line 735, in login
    raise last_exception
  File "/usr/local/lib/python3.7/smtplib.py", line 726, in login
    initial_response_ok=initial_response_ok)
  File "/usr/local/lib/python3.7/smtplib.py", line 647, in auth
    raise SMTPAuthenticationError(code, resp)
smtplib.SMTPAuthenticationError: (535, b'5.7.8 Username and Password not accepted. For more information, go to\n5.7.8  https://support.google.com/mail/?p=BadCredentials r5-20020a0562140c4500b00696127dc878sm53754qvj.12 - gsmtp')
[2024-03-17T01:29:27.847+0000] {taskinstance.py:1323} INFO - Marking task as FAILED. dag_id=Airflow_Lab2, task_id=send_email, execution_date=20240317T012913, start_date=20240317T012926, end_date=20240317T012927
[2024-03-17T01:29:27.852+0000] {email.py:268} INFO - Email alerting: attempt 1
[2024-03-17T01:29:28.704+0000] {taskinstance.py:1536} ERROR - Error when executing on_failure callback
Traceback (most recent call last):
  File "/home/airflow/.local/lib/python3.7/site-packages/airflow/models/taskinstance.py", line 1374, in _run_raw_task
    self._execute_task_with_callbacks(context, test_mode)
  File "/home/airflow/.local/lib/python3.7/site-packages/airflow/models/taskinstance.py", line 1520, in _execute_task_with_callbacks
    result = self._execute_task(context, task_orig)
  File "/home/airflow/.local/lib/python3.7/site-packages/airflow/models/taskinstance.py", line 1581, in _execute_task
    result = execute_callable(context=context)
  File "/home/airflow/.local/lib/python3.7/site-packages/airflow/operators/email.py", line 87, in execute
    custom_headers=self.custom_headers,
  File "/home/airflow/.local/lib/python3.7/site-packages/airflow/utils/email.py", line 91, in send_email
    **kwargs,
  File "/home/airflow/.local/lib/python3.7/site-packages/airflow/utils/email.py", line 152, in send_email_smtp
    send_mime_email(e_from=mail_from, e_to=recipients, mime_msg=msg, conn_id=conn_id, dryrun=dryrun)
  File "/home/airflow/.local/lib/python3.7/site-packages/airflow/utils/email.py", line 279, in send_mime_email
    smtp_conn.login(smtp_user, smtp_password)
  File "/usr/local/lib/python3.7/smtplib.py", line 735, in login
    raise last_exception
  File "/usr/local/lib/python3.7/smtplib.py", line 726, in login
    initial_response_ok=initial_response_ok)
  File "/usr/local/lib/python3.7/smtplib.py", line 647, in auth
    raise SMTPAuthenticationError(code, resp)
smtplib.SMTPAuthenticationError: (535, b'5.7.8 Username and Password not accepted. For more information, go to\n5.7.8  https://support.google.com/mail/?p=BadCredentials r5-20020a0562140c4500b00696127dc878sm53754qvj.12 - gsmtp')

During handling of the above exception, another exception occurred:

Traceback (most recent call last):
  File "/home/airflow/.local/lib/python3.7/site-packages/airflow/models/taskinstance.py", line 1534, in _run_finished_callback
    callback(context)
  File "/opt/airflow/dags/main.py", line 42, in notify_failure
    failure_email.execute(context=context)
  File "/home/airflow/.local/lib/python3.7/site-packages/airflow/operators/email.py", line 87, in execute
    custom_headers=self.custom_headers,
  File "/home/airflow/.local/lib/python3.7/site-packages/airflow/utils/email.py", line 91, in send_email
    **kwargs,
  File "/home/airflow/.local/lib/python3.7/site-packages/airflow/utils/email.py", line 152, in send_email_smtp
    send_mime_email(e_from=mail_from, e_to=recipients, mime_msg=msg, conn_id=conn_id, dryrun=dryrun)
  File "/home/airflow/.local/lib/python3.7/site-packages/airflow/utils/email.py", line 279, in send_mime_email
    smtp_conn.login(smtp_user, smtp_password)
  File "/usr/local/lib/python3.7/smtplib.py", line 735, in login
    raise last_exception
  File "/usr/local/lib/python3.7/smtplib.py", line 726, in login
    initial_response_ok=initial_response_ok)
  File "/usr/local/lib/python3.7/smtplib.py", line 647, in auth
    raise SMTPAuthenticationError(code, resp)
smtplib.SMTPAuthenticationError: (535, b'5.7.8 Username and Password not accepted. For more information, go to\n5.7.8  https://support.google.com/mail/?p=BadCredentials pt10-20020a056214048a00b00690494d2766sm3639705qvb.96 - gsmtp')
[2024-03-17T01:29:28.733+0000] {standard_task_runner.py:105} ERROR - Failed to execute job 64 for task send_email ((535, b'5.7.8 Username and Password not accepted. For more information, go to\n5.7.8  https://support.google.com/mail/?p=BadCredentials r5-20020a0562140c4500b00696127dc878sm53754qvj.12 - gsmtp'); 2022)
[2024-03-17T01:29:28.781+0000] {local_task_job.py:208} INFO - Task exited with return code 1
[2024-03-17T01:29:28.815+0000] {taskinstance.py:2578} INFO - 1 downstream tasks scheduled from follow-on schedule check
